[2023-06-21 23:50:28,090] INFO _log() L224   * Restarting with stat - call_trace=/home/leandro/Documentos/Treinamentos/P√≥s Engenharia Software/MVP1/myProjects/app_api/env/lib/python3.11/site-packages/werkzeug/_internal.py L224 
[2023-06-21 23:50:53,332] WARNING add_aplicacao() L71   Erro ao adicionar a aplica√ß√£o 'VAI', N√£o foi poss√≠vel salva novo item :/<class 'SystemError'> - call_trace=/home/leandro/Documentos/Treinamentos/P√≥s Engenharia Software/MVP1/myProjects/app_api/app.py L71  
[2023-06-21 23:50:53,334] INFO _log() L224  127.0.0.1 - - [21/Jun/2023 23:50:53] "[31m[1mPOST /aplicacao HTTP/1.1[0m" 400 - - call_trace=/home/leandro/Documentos/Treinamentos/P√≥s Engenharia Software/MVP1/myProjects/app_api/env/lib/python3.11/site-packages/werkzeug/_internal.py L224 
[2023-06-21 23:53:23,775] INFO _log() L224   * Detected change in '/home/leandro/Documentos/Treinamentos/P√≥s Engenharia Software/MVP1/myProjects/app_api/app.py', reloading - call_trace=/home/leandro/Documentos/Treinamentos/P√≥s Engenharia Software/MVP1/myProjects/app_api/env/lib/python3.11/site-packages/werkzeug/_internal.py L224 
[2023-06-21 23:53:23,909] INFO _log() L224   * Restarting with stat - call_trace=/home/leandro/Documentos/Treinamentos/P√≥s Engenharia Software/MVP1/myProjects/app_api/env/lib/python3.11/site-packages/werkzeug/_internal.py L224 
[2023-06-21 23:53:37,289] ERROR log_exception() L1449 Exception on /aplicacao [POST] - call_trace=/home/leandro/Documentos/Treinamentos/P√≥s Engenharia Software/MVP1/myProjects/app_api/env/lib/python3.11/site-packages/flask/app.py L1449
Traceback (most recent call last):
  File "/home/leandro/Documentos/Treinamentos/P√≥s Engenharia Software/MVP1/myProjects/app_api/app.py", line 60, in add_aplicacao
    return apresenta_aplicacoes(aplicacao), 200
           ^^^^^^^^^^^^^^^^^^^^^^^^^^^^^^^
  File "/home/leandro/Documentos/Treinamentos/P√≥s Engenharia Software/MVP1/myProjects/app_api/schemas/aplicacao.py", line 34, in apresenta_aplicacoes
    for aplicacao in aplicacoes:
TypeError: 'Aplicacao' object is not iterable

During handling of the above exception, another exception occurred:

Traceback (most recent call last):
  File "/home/leandro/Documentos/Treinamentos/P√≥s Engenharia Software/MVP1/myProjects/app_api/env/lib/python3.11/site-packages/flask/app.py", line 2073, in wsgi_app
    response = self.full_dispatch_request()
               ^^^^^^^^^^^^^^^^^^^^^^^^^^^^
  File "/home/leandro/Documentos/Treinamentos/P√≥s Engenharia Software/MVP1/myProjects/app_api/env/lib/python3.11/site-packages/flask/app.py", line 1519, in full_dispatch_request
    rv = self.handle_user_exception(e)
         ^^^^^^^^^^^^^^^^^^^^^^^^^^^^^
  File "/home/leandro/Documentos/Treinamentos/P√≥s Engenharia Software/MVP1/myProjects/app_api/env/lib/python3.11/site-packages/flask_cors/extension.py", line 165, in wrapped_function
    return cors_after_request(app.make_response(f(*args, **kwargs)))
                                                ^^^^^^^^^^^^^^^^^^
  File "/home/leandro/Documentos/Treinamentos/P√≥s Engenharia Software/MVP1/myProjects/app_api/env/lib/python3.11/site-packages/flask/app.py", line 1517, in full_dispatch_request
    rv = self.dispatch_request()
         ^^^^^^^^^^^^^^^^^^^^^^^
  File "/home/leandro/Documentos/Treinamentos/P√≥s Engenharia Software/MVP1/myProjects/app_api/env/lib/python3.11/site-packages/flask/app.py", line 1503, in dispatch_request
    return self.ensure_sync(self.view_functions[rule.endpoint])(**req.view_args)
           ^^^^^^^^^^^^^^^^^^^^^^^^^^^^^^^^^^^^^^^^^^^^^^^^^^^^^^^^^^^^^^^^^^^^^
  File "/home/leandro/Documentos/Treinamentos/P√≥s Engenharia Software/MVP1/myProjects/app_api/env/lib/python3.11/site-packages/flask_openapi3/scaffold.py", line 191, in wrapper
    resp = _do_wrapper(
           ^^^^^^^^^^^^
  File "/home/leandro/Documentos/Treinamentos/P√≥s Engenharia Software/MVP1/myProjects/app_api/env/lib/python3.11/site-packages/flask_openapi3/do_wrapper.py", line 135, in _do_wrapper
    response = func(**request_kwargs)
               ^^^^^^^^^^^^^^^^^^^^^^
  File "/home/leandro/Documentos/Treinamentos/P√≥s Engenharia Software/MVP1/myProjects/app_api/app.py", line 70, in add_aplicacao
    error_msg = "N√£o foi poss√≠vel salva novo item :/" + type(e) + " - "+ e.exceptions
                ~~~~~~~~~~~~~~~~~~~~~~~~~~~~~~~~~~~~~~~~^^~~~~~
TypeError: can only concatenate str (not "type") to str
[2023-06-21 23:53:37,293] INFO _log() L224  127.0.0.1 - - [21/Jun/2023 23:53:37] "[35m[1mPOST /aplicacao HTTP/1.1[0m" 500 - - call_trace=/home/leandro/Documentos/Treinamentos/P√≥s Engenharia Software/MVP1/myProjects/app_api/env/lib/python3.11/site-packages/werkzeug/_internal.py L224 
[2023-06-21 23:54:07,531] INFO _log() L224   * Detected change in '/home/leandro/Documentos/Treinamentos/P√≥s Engenharia Software/MVP1/myProjects/app_api/app.py', reloading - call_trace=/home/leandro/Documentos/Treinamentos/P√≥s Engenharia Software/MVP1/myProjects/app_api/env/lib/python3.11/site-packages/werkzeug/_internal.py L224 
[2023-06-21 23:54:07,653] INFO _log() L224   * Restarting with stat - call_trace=/home/leandro/Documentos/Treinamentos/P√≥s Engenharia Software/MVP1/myProjects/app_api/env/lib/python3.11/site-packages/werkzeug/_internal.py L224 
[2023-06-21 23:54:09,618] WARNING add_aplicacao() L65   Erro ao adicionar a aplica√ß√£o 'www', Aplica√ß√£o de mesmo nome j√° salvo na base:/ - call_trace=/home/leandro/Documentos/Treinamentos/P√≥s Engenharia Software/MVP1/myProjects/app_api/app.py L65  
[2023-06-21 23:54:09,620] INFO _log() L224  127.0.0.1 - - [21/Jun/2023 23:54:09] "[31m[1mPOST /aplicacao HTTP/1.1[0m" 409 - - call_trace=/home/leandro/Documentos/Treinamentos/P√≥s Engenharia Software/MVP1/myProjects/app_api/env/lib/python3.11/site-packages/werkzeug/_internal.py L224 
[2023-06-21 23:54:23,524] ERROR log_exception() L1449 Exception on /aplicacao [POST] - call_trace=/home/leandro/Documentos/Treinamentos/P√≥s Engenharia Software/MVP1/myProjects/app_api/env/lib/python3.11/site-packages/flask/app.py L1449
Traceback (most recent call last):
  File "/home/leandro/Documentos/Treinamentos/P√≥s Engenharia Software/MVP1/myProjects/app_api/app.py", line 60, in add_aplicacao
    return apresenta_aplicacoes(aplicacao), 200
           ^^^^^^^^^^^^^^^^^^^^^^^^^^^^^^^
  File "/home/leandro/Documentos/Treinamentos/P√≥s Engenharia Software/MVP1/myProjects/app_api/schemas/aplicacao.py", line 34, in apresenta_aplicacoes
    for aplicacao in aplicacoes:
TypeError: 'Aplicacao' object is not iterable

During handling of the above exception, another exception occurred:

Traceback (most recent call last):
  File "/home/leandro/Documentos/Treinamentos/P√≥s Engenharia Software/MVP1/myProjects/app_api/env/lib/python3.11/site-packages/flask/app.py", line 2073, in wsgi_app
    response = self.full_dispatch_request()
               ^^^^^^^^^^^^^^^^^^^^^^^^^^^^
  File "/home/leandro/Documentos/Treinamentos/P√≥s Engenharia Software/MVP1/myProjects/app_api/env/lib/python3.11/site-packages/flask/app.py", line 1519, in full_dispatch_request
    rv = self.handle_user_exception(e)
         ^^^^^^^^^^^^^^^^^^^^^^^^^^^^^
  File "/home/leandro/Documentos/Treinamentos/P√≥s Engenharia Software/MVP1/myProjects/app_api/env/lib/python3.11/site-packages/flask_cors/extension.py", line 165, in wrapped_function
    return cors_after_request(app.make_response(f(*args, **kwargs)))
                                                ^^^^^^^^^^^^^^^^^^
  File "/home/leandro/Documentos/Treinamentos/P√≥s Engenharia Software/MVP1/myProjects/app_api/env/lib/python3.11/site-packages/flask/app.py", line 1517, in full_dispatch_request
    rv = self.dispatch_request()
         ^^^^^^^^^^^^^^^^^^^^^^^
  File "/home/leandro/Documentos/Treinamentos/P√≥s Engenharia Software/MVP1/myProjects/app_api/env/lib/python3.11/site-packages/flask/app.py", line 1503, in dispatch_request
    return self.ensure_sync(self.view_functions[rule.endpoint])(**req.view_args)
           ^^^^^^^^^^^^^^^^^^^^^^^^^^^^^^^^^^^^^^^^^^^^^^^^^^^^^^^^^^^^^^^^^^^^^
  File "/home/leandro/Documentos/Treinamentos/P√≥s Engenharia Software/MVP1/myProjects/app_api/env/lib/python3.11/site-packages/flask_openapi3/scaffold.py", line 191, in wrapper
    resp = _do_wrapper(
           ^^^^^^^^^^^^
  File "/home/leandro/Documentos/Treinamentos/P√≥s Engenharia Software/MVP1/myProjects/app_api/env/lib/python3.11/site-packages/flask_openapi3/do_wrapper.py", line 135, in _do_wrapper
    response = func(**request_kwargs)
               ^^^^^^^^^^^^^^^^^^^^^^
  File "/home/leandro/Documentos/Treinamentos/P√≥s Engenharia Software/MVP1/myProjects/app_api/app.py", line 70, in add_aplicacao
    error_msg = "N√£o foi poss√≠vel salva novo item :/" + str(type(e)) + " - "+ e.exceptions
                                                                              ^^^^^^^^^^^^
AttributeError: 'TypeError' object has no attribute 'exceptions'
[2023-06-21 23:54:23,527] INFO _log() L224  127.0.0.1 - - [21/Jun/2023 23:54:23] "[35m[1mPOST /aplicacao HTTP/1.1[0m" 500 - - call_trace=/home/leandro/Documentos/Treinamentos/P√≥s Engenharia Software/MVP1/myProjects/app_api/env/lib/python3.11/site-packages/werkzeug/_internal.py L224 
[2023-06-21 23:54:48,243] INFO _log() L224   * Detected change in '/home/leandro/Documentos/Treinamentos/P√≥s Engenharia Software/MVP1/myProjects/app_api/app.py', reloading - call_trace=/home/leandro/Documentos/Treinamentos/P√≥s Engenharia Software/MVP1/myProjects/app_api/env/lib/python3.11/site-packages/werkzeug/_internal.py L224 
[2023-06-21 23:54:48,371] INFO _log() L224   * Restarting with stat - call_trace=/home/leandro/Documentos/Treinamentos/P√≥s Engenharia Software/MVP1/myProjects/app_api/env/lib/python3.11/site-packages/werkzeug/_internal.py L224 
[2023-06-21 23:55:59,304] INFO _log() L224   * Restarting with stat - call_trace=/home/leandro/Documentos/Treinamentos/P√≥s Engenharia Software/MVP1/myProjects/app_api/env/lib/python3.11/site-packages/werkzeug/_internal.py L224 
