[2023-07-09 19:38:37,260] ERROR log_exception() L1449 Exception on /aplicacao [PUT] - call_trace=/home/leandro/Documentos/Treinamentos/Pós Engenharia Software/MVP1/myProjects/app_api/env/lib/python3.11/site-packages/flask/app.py L1449
Traceback (most recent call last):
  File "/home/leandro/Documentos/Treinamentos/Pós Engenharia Software/MVP1/myProjects/app_api/env/lib/python3.11/site-packages/sqlalchemy/engine/base.py", line 1900, in _execute_context
    self.dialect.do_execute(
  File "/home/leandro/Documentos/Treinamentos/Pós Engenharia Software/MVP1/myProjects/app_api/env/lib/python3.11/site-packages/sqlalchemy/engine/default.py", line 736, in do_execute
    cursor.execute(statement, parameters)
sqlite3.IntegrityError: UNIQUE constraint failed: aplicacao.nome

The above exception was the direct cause of the following exception:

Traceback (most recent call last):
  File "/home/leandro/Documentos/Treinamentos/Pós Engenharia Software/MVP1/myProjects/app_api/app.py", line 340, in upd_aplicacao
    session.commit()
  File "/home/leandro/Documentos/Treinamentos/Pós Engenharia Software/MVP1/myProjects/app_api/env/lib/python3.11/site-packages/sqlalchemy/orm/session.py", line 1451, in commit
    self._transaction.commit(_to_root=self.future)
  File "/home/leandro/Documentos/Treinamentos/Pós Engenharia Software/MVP1/myProjects/app_api/env/lib/python3.11/site-packages/sqlalchemy/orm/session.py", line 829, in commit
    self._prepare_impl()
  File "/home/leandro/Documentos/Treinamentos/Pós Engenharia Software/MVP1/myProjects/app_api/env/lib/python3.11/site-packages/sqlalchemy/orm/session.py", line 808, in _prepare_impl
    self.session.flush()
  File "/home/leandro/Documentos/Treinamentos/Pós Engenharia Software/MVP1/myProjects/app_api/env/lib/python3.11/site-packages/sqlalchemy/orm/session.py", line 3386, in flush
    self._flush(objects)
  File "/home/leandro/Documentos/Treinamentos/Pós Engenharia Software/MVP1/myProjects/app_api/env/lib/python3.11/site-packages/sqlalchemy/orm/session.py", line 3525, in _flush
    with util.safe_reraise():
  File "/home/leandro/Documentos/Treinamentos/Pós Engenharia Software/MVP1/myProjects/app_api/env/lib/python3.11/site-packages/sqlalchemy/util/langhelpers.py", line 70, in __exit__
    compat.raise_(
  File "/home/leandro/Documentos/Treinamentos/Pós Engenharia Software/MVP1/myProjects/app_api/env/lib/python3.11/site-packages/sqlalchemy/util/compat.py", line 208, in raise_
    raise exception
  File "/home/leandro/Documentos/Treinamentos/Pós Engenharia Software/MVP1/myProjects/app_api/env/lib/python3.11/site-packages/sqlalchemy/orm/session.py", line 3486, in _flush
    flush_context.execute()
  File "/home/leandro/Documentos/Treinamentos/Pós Engenharia Software/MVP1/myProjects/app_api/env/lib/python3.11/site-packages/sqlalchemy/orm/unitofwork.py", line 456, in execute
    rec.execute(self)
  File "/home/leandro/Documentos/Treinamentos/Pós Engenharia Software/MVP1/myProjects/app_api/env/lib/python3.11/site-packages/sqlalchemy/orm/unitofwork.py", line 630, in execute
    util.preloaded.orm_persistence.save_obj(
  File "/home/leandro/Documentos/Treinamentos/Pós Engenharia Software/MVP1/myProjects/app_api/env/lib/python3.11/site-packages/sqlalchemy/orm/persistence.py", line 237, in save_obj
    _emit_update_statements(
  File "/home/leandro/Documentos/Treinamentos/Pós Engenharia Software/MVP1/myProjects/app_api/env/lib/python3.11/site-packages/sqlalchemy/orm/persistence.py", line 1001, in _emit_update_statements
    c = connection._execute_20(
        ^^^^^^^^^^^^^^^^^^^^^^^
  File "/home/leandro/Documentos/Treinamentos/Pós Engenharia Software/MVP1/myProjects/app_api/env/lib/python3.11/site-packages/sqlalchemy/engine/base.py", line 1705, in _execute_20
    return meth(self, args_10style, kwargs_10style, execution_options)
           ^^^^^^^^^^^^^^^^^^^^^^^^^^^^^^^^^^^^^^^^^^^^^^^^^^^^^^^^^^^
  File "/home/leandro/Documentos/Treinamentos/Pós Engenharia Software/MVP1/myProjects/app_api/env/lib/python3.11/site-packages/sqlalchemy/sql/elements.py", line 333, in _execute_on_connection
    return connection._execute_clauseelement(
           ^^^^^^^^^^^^^^^^^^^^^^^^^^^^^^^^^^
  File "/home/leandro/Documentos/Treinamentos/Pós Engenharia Software/MVP1/myProjects/app_api/env/lib/python3.11/site-packages/sqlalchemy/engine/base.py", line 1572, in _execute_clauseelement
    ret = self._execute_context(
          ^^^^^^^^^^^^^^^^^^^^^^
  File "/home/leandro/Documentos/Treinamentos/Pós Engenharia Software/MVP1/myProjects/app_api/env/lib/python3.11/site-packages/sqlalchemy/engine/base.py", line 1943, in _execute_context
    self._handle_dbapi_exception(
  File "/home/leandro/Documentos/Treinamentos/Pós Engenharia Software/MVP1/myProjects/app_api/env/lib/python3.11/site-packages/sqlalchemy/engine/base.py", line 2124, in _handle_dbapi_exception
    util.raise_(
  File "/home/leandro/Documentos/Treinamentos/Pós Engenharia Software/MVP1/myProjects/app_api/env/lib/python3.11/site-packages/sqlalchemy/util/compat.py", line 208, in raise_
    raise exception
  File "/home/leandro/Documentos/Treinamentos/Pós Engenharia Software/MVP1/myProjects/app_api/env/lib/python3.11/site-packages/sqlalchemy/engine/base.py", line 1900, in _execute_context
    self.dialect.do_execute(
  File "/home/leandro/Documentos/Treinamentos/Pós Engenharia Software/MVP1/myProjects/app_api/env/lib/python3.11/site-packages/sqlalchemy/engine/default.py", line 736, in do_execute
    cursor.execute(statement, parameters)
sqlalchemy.exc.IntegrityError: (sqlite3.IntegrityError) UNIQUE constraint failed: aplicacao.nome
[SQL: UPDATE aplicacao SET nome=? WHERE aplicacao.pk_aplicacao = ?]
[parameters: ('SAP Success Factor', 2)]
(Background on this error at: https://sqlalche.me/e/14/gkpj)

During handling of the above exception, another exception occurred:

Traceback (most recent call last):
  File "/home/leandro/Documentos/Treinamentos/Pós Engenharia Software/MVP1/myProjects/app_api/env/lib/python3.11/site-packages/flask/app.py", line 2073, in wsgi_app
    response = self.full_dispatch_request()
               ^^^^^^^^^^^^^^^^^^^^^^^^^^^^
  File "/home/leandro/Documentos/Treinamentos/Pós Engenharia Software/MVP1/myProjects/app_api/env/lib/python3.11/site-packages/flask/app.py", line 1519, in full_dispatch_request
    rv = self.handle_user_exception(e)
         ^^^^^^^^^^^^^^^^^^^^^^^^^^^^^
  File "/home/leandro/Documentos/Treinamentos/Pós Engenharia Software/MVP1/myProjects/app_api/env/lib/python3.11/site-packages/flask_cors/extension.py", line 165, in wrapped_function
    return cors_after_request(app.make_response(f(*args, **kwargs)))
                                                ^^^^^^^^^^^^^^^^^^
  File "/home/leandro/Documentos/Treinamentos/Pós Engenharia Software/MVP1/myProjects/app_api/env/lib/python3.11/site-packages/flask/app.py", line 1517, in full_dispatch_request
    rv = self.dispatch_request()
         ^^^^^^^^^^^^^^^^^^^^^^^
  File "/home/leandro/Documentos/Treinamentos/Pós Engenharia Software/MVP1/myProjects/app_api/env/lib/python3.11/site-packages/flask/app.py", line 1503, in dispatch_request
    return self.ensure_sync(self.view_functions[rule.endpoint])(**req.view_args)
           ^^^^^^^^^^^^^^^^^^^^^^^^^^^^^^^^^^^^^^^^^^^^^^^^^^^^^^^^^^^^^^^^^^^^^
  File "/home/leandro/Documentos/Treinamentos/Pós Engenharia Software/MVP1/myProjects/app_api/env/lib/python3.11/site-packages/flask_openapi3/scaffold.py", line 273, in wrapper
    resp = _do_wrapper(
           ^^^^^^^^^^^^
  File "/home/leandro/Documentos/Treinamentos/Pós Engenharia Software/MVP1/myProjects/app_api/env/lib/python3.11/site-packages/flask_openapi3/do_wrapper.py", line 135, in _do_wrapper
    response = func(**request_kwargs)
               ^^^^^^^^^^^^^^^^^^^^^^
  File "/home/leandro/Documentos/Treinamentos/Pós Engenharia Software/MVP1/myProjects/app_api/app.py", line 354, in upd_aplicacao
    logger.warning(f"Erro ao adicionar aplicação '{db_aplicacao.nome}', {error_msg}")
                                                   ^^^^^^^^^^^^^^^^^
  File "/home/leandro/Documentos/Treinamentos/Pós Engenharia Software/MVP1/myProjects/app_api/env/lib/python3.11/site-packages/sqlalchemy/orm/attributes.py", line 482, in __get__
    return self.impl.get(state, dict_)
           ^^^^^^^^^^^^^^^^^^^^^^^^^^^
  File "/home/leandro/Documentos/Treinamentos/Pós Engenharia Software/MVP1/myProjects/app_api/env/lib/python3.11/site-packages/sqlalchemy/orm/attributes.py", line 942, in get
    value = self._fire_loader_callables(state, key, passive)
            ^^^^^^^^^^^^^^^^^^^^^^^^^^^^^^^^^^^^^^^^^^^^^^^^
  File "/home/leandro/Documentos/Treinamentos/Pós Engenharia Software/MVP1/myProjects/app_api/env/lib/python3.11/site-packages/sqlalchemy/orm/attributes.py", line 973, in _fire_loader_callables
    return state._load_expired(state, passive)
           ^^^^^^^^^^^^^^^^^^^^^^^^^^^^^^^^^^^
  File "/home/leandro/Documentos/Treinamentos/Pós Engenharia Software/MVP1/myProjects/app_api/env/lib/python3.11/site-packages/sqlalchemy/orm/state.py", line 712, in _load_expired
    self.manager.expired_attribute_loader(self, toload, passive)
  File "/home/leandro/Documentos/Treinamentos/Pós Engenharia Software/MVP1/myProjects/app_api/env/lib/python3.11/site-packages/sqlalchemy/orm/loading.py", line 1451, in load_scalar_attributes
    result = load_on_ident(
             ^^^^^^^^^^^^^^
  File "/home/leandro/Documentos/Treinamentos/Pós Engenharia Software/MVP1/myProjects/app_api/env/lib/python3.11/site-packages/sqlalchemy/orm/loading.py", line 407, in load_on_ident
    return load_on_pk_identity(
           ^^^^^^^^^^^^^^^^^^^^
  File "/home/leandro/Documentos/Treinamentos/Pós Engenharia Software/MVP1/myProjects/app_api/env/lib/python3.11/site-packages/sqlalchemy/orm/loading.py", line 530, in load_on_pk_identity
    session.execute(
  File "/home/leandro/Documentos/Treinamentos/Pós Engenharia Software/MVP1/myProjects/app_api/env/lib/python3.11/site-packages/sqlalchemy/orm/session.py", line 1711, in execute
    conn = self._connection_for_bind(bind)
           ^^^^^^^^^^^^^^^^^^^^^^^^^^^^^^^
  File "/home/leandro/Documentos/Treinamentos/Pós Engenharia Software/MVP1/myProjects/app_api/env/lib/python3.11/site-packages/sqlalchemy/orm/session.py", line 1552, in _connection_for_bind
    return self._transaction._connection_for_bind(
           ^^^^^^^^^^^^^^^^^^^^^^^^^^^^^^^^^^^^^^^
  File "/home/leandro/Documentos/Treinamentos/Pós Engenharia Software/MVP1/myProjects/app_api/env/lib/python3.11/site-packages/sqlalchemy/orm/session.py", line 721, in _connection_for_bind
    self._assert_active()
  File "/home/leandro/Documentos/Treinamentos/Pós Engenharia Software/MVP1/myProjects/app_api/env/lib/python3.11/site-packages/sqlalchemy/orm/session.py", line 601, in _assert_active
    raise sa_exc.PendingRollbackError(
sqlalchemy.exc.PendingRollbackError: This Session's transaction has been rolled back due to a previous exception during flush. To begin a new transaction with this Session, first issue Session.rollback(). Original exception was: (sqlite3.IntegrityError) UNIQUE constraint failed: aplicacao.nome
[SQL: UPDATE aplicacao SET nome=? WHERE aplicacao.pk_aplicacao = ?]
[parameters: ('SAP Success Factor', 2)]
(Background on this error at: https://sqlalche.me/e/14/gkpj) (Background on this error at: https://sqlalche.me/e/14/7s2a)
