[2023-06-21 23:54:57,047] ERROR log_exception() L1449 Exception on /aplicacao [POST] - call_trace=/home/leandro/Documentos/Treinamentos/P√≥s Engenharia Software/MVP1/myProjects/app_api/env/lib/python3.11/site-packages/flask/app.py L1449
Traceback (most recent call last):
  File "/home/leandro/Documentos/Treinamentos/P√≥s Engenharia Software/MVP1/myProjects/app_api/app.py", line 60, in add_aplicacao
    return apresenta_aplicacoes(aplicacao), 200
           ^^^^^^^^^^^^^^^^^^^^^^^^^^^^^^^
  File "/home/leandro/Documentos/Treinamentos/P√≥s Engenharia Software/MVP1/myProjects/app_api/schemas/aplicacao.py", line 34, in apresenta_aplicacoes
    for aplicacao in aplicacoes:
TypeError: 'Aplicacao' object is not iterable

During handling of the above exception, another exception occurred:

Traceback (most recent call last):
  File "/home/leandro/Documentos/Treinamentos/P√≥s Engenharia Software/MVP1/myProjects/app_api/env/lib/python3.11/site-packages/flask/app.py", line 2073, in wsgi_app
    response = self.full_dispatch_request()
               ^^^^^^^^^^^^^^^^^^^^^^^^^^^^
  File "/home/leandro/Documentos/Treinamentos/P√≥s Engenharia Software/MVP1/myProjects/app_api/env/lib/python3.11/site-packages/flask/app.py", line 1519, in full_dispatch_request
    rv = self.handle_user_exception(e)
         ^^^^^^^^^^^^^^^^^^^^^^^^^^^^^
  File "/home/leandro/Documentos/Treinamentos/P√≥s Engenharia Software/MVP1/myProjects/app_api/env/lib/python3.11/site-packages/flask_cors/extension.py", line 165, in wrapped_function
    return cors_after_request(app.make_response(f(*args, **kwargs)))
                                                ^^^^^^^^^^^^^^^^^^
  File "/home/leandro/Documentos/Treinamentos/P√≥s Engenharia Software/MVP1/myProjects/app_api/env/lib/python3.11/site-packages/flask/app.py", line 1517, in full_dispatch_request
    rv = self.dispatch_request()
         ^^^^^^^^^^^^^^^^^^^^^^^
  File "/home/leandro/Documentos/Treinamentos/P√≥s Engenharia Software/MVP1/myProjects/app_api/env/lib/python3.11/site-packages/flask/app.py", line 1503, in dispatch_request
    return self.ensure_sync(self.view_functions[rule.endpoint])(**req.view_args)
           ^^^^^^^^^^^^^^^^^^^^^^^^^^^^^^^^^^^^^^^^^^^^^^^^^^^^^^^^^^^^^^^^^^^^^
  File "/home/leandro/Documentos/Treinamentos/P√≥s Engenharia Software/MVP1/myProjects/app_api/env/lib/python3.11/site-packages/flask_openapi3/scaffold.py", line 191, in wrapper
    resp = _do_wrapper(
           ^^^^^^^^^^^^
  File "/home/leandro/Documentos/Treinamentos/P√≥s Engenharia Software/MVP1/myProjects/app_api/env/lib/python3.11/site-packages/flask_openapi3/do_wrapper.py", line 135, in _do_wrapper
    response = func(**request_kwargs)
               ^^^^^^^^^^^^^^^^^^^^^^
  File "/home/leandro/Documentos/Treinamentos/P√≥s Engenharia Software/MVP1/myProjects/app_api/app.py", line 70, in add_aplicacao
    error_msg = "N√£o foi poss√≠vel salva novo item :/" + str(type(e)) + " - "+ str(e.exceptions)
                                                                                  ^^^^^^^^^^^^
AttributeError: 'TypeError' object has no attribute 'exceptions'
[2023-06-21 23:54:57,051] INFO _log() L224  127.0.0.1 - - [21/Jun/2023 23:54:57] "[35m[1mPOST /aplicacao HTTP/1.1[0m" 500 - - call_trace=/home/leandro/Documentos/Treinamentos/P√≥s Engenharia Software/MVP1/myProjects/app_api/env/lib/python3.11/site-packages/werkzeug/_internal.py L224 
[2023-06-21 23:55:59,178] INFO _log() L224   * Detected change in '/home/leandro/Documentos/Treinamentos/P√≥s Engenharia Software/MVP1/myProjects/app_api/app.py', reloading - call_trace=/home/leandro/Documentos/Treinamentos/P√≥s Engenharia Software/MVP1/myProjects/app_api/env/lib/python3.11/site-packages/werkzeug/_internal.py L224 
[2023-06-21 23:56:09,202] ERROR log_exception() L1449 Exception on /aplicacao [POST] - call_trace=/home/leandro/Documentos/Treinamentos/P√≥s Engenharia Software/MVP1/myProjects/app_api/env/lib/python3.11/site-packages/flask/app.py L1449
Traceback (most recent call last):
  File "/home/leandro/Documentos/Treinamentos/P√≥s Engenharia Software/MVP1/myProjects/app_api/app.py", line 60, in add_aplicacao
    return apresenta_aplicacoes(aplicacao), 200
           ^^^^^^^^^^^^^^^^^^^^^^^^^^^^^^^
  File "/home/leandro/Documentos/Treinamentos/P√≥s Engenharia Software/MVP1/myProjects/app_api/schemas/aplicacao.py", line 34, in apresenta_aplicacoes
    for aplicacao in aplicacoes:
TypeError: 'Aplicacao' object is not iterable

During handling of the above exception, another exception occurred:

Traceback (most recent call last):
  File "/home/leandro/Documentos/Treinamentos/P√≥s Engenharia Software/MVP1/myProjects/app_api/env/lib/python3.11/site-packages/flask/app.py", line 2073, in wsgi_app
    response = self.full_dispatch_request()
               ^^^^^^^^^^^^^^^^^^^^^^^^^^^^
  File "/home/leandro/Documentos/Treinamentos/P√≥s Engenharia Software/MVP1/myProjects/app_api/env/lib/python3.11/site-packages/flask/app.py", line 1519, in full_dispatch_request
    rv = self.handle_user_exception(e)
         ^^^^^^^^^^^^^^^^^^^^^^^^^^^^^
  File "/home/leandro/Documentos/Treinamentos/P√≥s Engenharia Software/MVP1/myProjects/app_api/env/lib/python3.11/site-packages/flask_cors/extension.py", line 165, in wrapped_function
    return cors_after_request(app.make_response(f(*args, **kwargs)))
                                                ^^^^^^^^^^^^^^^^^^
  File "/home/leandro/Documentos/Treinamentos/P√≥s Engenharia Software/MVP1/myProjects/app_api/env/lib/python3.11/site-packages/flask/app.py", line 1517, in full_dispatch_request
    rv = self.dispatch_request()
         ^^^^^^^^^^^^^^^^^^^^^^^
  File "/home/leandro/Documentos/Treinamentos/P√≥s Engenharia Software/MVP1/myProjects/app_api/env/lib/python3.11/site-packages/flask/app.py", line 1503, in dispatch_request
    return self.ensure_sync(self.view_functions[rule.endpoint])(**req.view_args)
           ^^^^^^^^^^^^^^^^^^^^^^^^^^^^^^^^^^^^^^^^^^^^^^^^^^^^^^^^^^^^^^^^^^^^^
  File "/home/leandro/Documentos/Treinamentos/P√≥s Engenharia Software/MVP1/myProjects/app_api/env/lib/python3.11/site-packages/flask_openapi3/scaffold.py", line 191, in wrapper
    resp = _do_wrapper(
           ^^^^^^^^^^^^
  File "/home/leandro/Documentos/Treinamentos/P√≥s Engenharia Software/MVP1/myProjects/app_api/env/lib/python3.11/site-packages/flask_openapi3/do_wrapper.py", line 135, in _do_wrapper
    response = func(**request_kwargs)
               ^^^^^^^^^^^^^^^^^^^^^^
  File "/home/leandro/Documentos/Treinamentos/P√≥s Engenharia Software/MVP1/myProjects/app_api/app.py", line 70, in add_aplicacao
    error_msg = f"N√£o foi poss√≠vel salva novo item :/ {type(e)} - {e.exceptions}"
                                                                   ^^^^^^^^^^^^
AttributeError: 'TypeError' object has no attribute 'exceptions'
[2023-06-21 23:56:09,205] INFO _log() L224  127.0.0.1 - - [21/Jun/2023 23:56:09] "[35m[1mPOST /aplicacao HTTP/1.1[0m" 500 - - call_trace=/home/leandro/Documentos/Treinamentos/P√≥s Engenharia Software/MVP1/myProjects/app_api/env/lib/python3.11/site-packages/werkzeug/_internal.py L224 
[2023-06-21 23:57:07,105] INFO _log() L224   * Detected change in '/home/leandro/Documentos/Treinamentos/P√≥s Engenharia Software/MVP1/myProjects/app_api/app.py', reloading - call_trace=/home/leandro/Documentos/Treinamentos/P√≥s Engenharia Software/MVP1/myProjects/app_api/env/lib/python3.11/site-packages/werkzeug/_internal.py L224 
