[2023-06-21 23:33:03,393] INFO _log() L224   * Restarting with stat - call_trace=/home/leandro/Documentos/Treinamentos/P√≥s Engenharia Software/MVP1/myProjects/app_api/env/lib/python3.11/site-packages/werkzeug/_internal.py L224 
[2023-06-21 23:38:54,480] INFO _log() L224   * Detected change in '/home/leandro/Documentos/Treinamentos/P√≥s Engenharia Software/MVP1/myProjects/app_api/schemas/aplicacao.py', reloading - call_trace=/home/leandro/Documentos/Treinamentos/P√≥s Engenharia Software/MVP1/myProjects/app_api/env/lib/python3.11/site-packages/werkzeug/_internal.py L224 
[2023-06-21 23:38:54,604] INFO _log() L224   * Restarting with stat - call_trace=/home/leandro/Documentos/Treinamentos/P√≥s Engenharia Software/MVP1/myProjects/app_api/env/lib/python3.11/site-packages/werkzeug/_internal.py L224 
[2023-06-21 23:40:33,709] INFO _log() L224   * Detected change in '/home/leandro/Documentos/Treinamentos/P√≥s Engenharia Software/MVP1/myProjects/app_api/app.py', reloading - call_trace=/home/leandro/Documentos/Treinamentos/P√≥s Engenharia Software/MVP1/myProjects/app_api/env/lib/python3.11/site-packages/werkzeug/_internal.py L224 
[2023-06-21 23:40:33,834] INFO _log() L224   * Restarting with stat - call_trace=/home/leandro/Documentos/Treinamentos/P√≥s Engenharia Software/MVP1/myProjects/app_api/env/lib/python3.11/site-packages/werkzeug/_internal.py L224 
[2023-06-21 23:40:49,102] INFO _log() L224  127.0.0.1 - - [21/Jun/2023 23:40:49] "GET /openapi/swagger HTTP/1.1" 200 - - call_trace=/home/leandro/Documentos/Treinamentos/P√≥s Engenharia Software/MVP1/myProjects/app_api/env/lib/python3.11/site-packages/werkzeug/_internal.py L224 
[2023-06-21 23:40:49,142] INFO _log() L224  127.0.0.1 - - [21/Jun/2023 23:40:49] "[36mGET /openapi/static/css/swagger-ui.css HTTP/1.1[0m" 304 - - call_trace=/home/leandro/Documentos/Treinamentos/P√≥s Engenharia Software/MVP1/myProjects/app_api/env/lib/python3.11/site-packages/werkzeug/_internal.py L224 
[2023-06-21 23:40:49,147] INFO _log() L224  127.0.0.1 - - [21/Jun/2023 23:40:49] "[36mGET /openapi/static/js/swagger-ui-bundle.js HTTP/1.1[0m" 304 - - call_trace=/home/leandro/Documentos/Treinamentos/P√≥s Engenharia Software/MVP1/myProjects/app_api/env/lib/python3.11/site-packages/werkzeug/_internal.py L224 
[2023-06-21 23:40:49,148] INFO _log() L224  127.0.0.1 - - [21/Jun/2023 23:40:49] "[36mGET /openapi/static/js/swagger-ui-standalone-preset.js HTTP/1.1[0m" 304 - - call_trace=/home/leandro/Documentos/Treinamentos/P√≥s Engenharia Software/MVP1/myProjects/app_api/env/lib/python3.11/site-packages/werkzeug/_internal.py L224 
[2023-06-21 23:40:49,547] INFO _log() L224  127.0.0.1 - - [21/Jun/2023 23:40:49] "GET /openapi/openapi.json HTTP/1.1" 200 - - call_trace=/home/leandro/Documentos/Treinamentos/P√≥s Engenharia Software/MVP1/myProjects/app_api/env/lib/python3.11/site-packages/werkzeug/_internal.py L224 
[2023-06-21 23:40:49,553] INFO _log() L224  127.0.0.1 - - [21/Jun/2023 23:40:49] "[36mGET /openapi/static/images/swagger.svg HTTP/1.1[0m" 304 - - call_trace=/home/leandro/Documentos/Treinamentos/P√≥s Engenharia Software/MVP1/myProjects/app_api/env/lib/python3.11/site-packages/werkzeug/_internal.py L224 
[2023-06-21 23:41:09,461] WARNING add_aplicacao() L71   Erro ao adicionar a aplica√ß√£o 'TESTE', N√£o foi poss√≠vel salva novo item :/ - call_trace=/home/leandro/Documentos/Treinamentos/P√≥s Engenharia Software/MVP1/myProjects/app_api/app.py L71  
[2023-06-21 23:41:09,462] INFO _log() L224  127.0.0.1 - - [21/Jun/2023 23:41:09] "[31m[1mPOST /aplicacao HTTP/1.1[0m" 400 - - call_trace=/home/leandro/Documentos/Treinamentos/P√≥s Engenharia Software/MVP1/myProjects/app_api/env/lib/python3.11/site-packages/werkzeug/_internal.py L224 
[2023-06-21 23:42:35,057] INFO _log() L224   * Detected change in '/home/leandro/Documentos/Treinamentos/P√≥s Engenharia Software/MVP1/myProjects/app_api/app.py', reloading - call_trace=/home/leandro/Documentos/Treinamentos/P√≥s Engenharia Software/MVP1/myProjects/app_api/env/lib/python3.11/site-packages/werkzeug/_internal.py L224 
[2023-06-21 23:42:35,187] INFO _log() L224   * Restarting with stat - call_trace=/home/leandro/Documentos/Treinamentos/P√≥s Engenharia Software/MVP1/myProjects/app_api/env/lib/python3.11/site-packages/werkzeug/_internal.py L224 
[2023-06-21 23:42:56,895] WARNING add_aplicacao() L71   Erro ao adicionar a aplica√ß√£o 'OUTRO TESTE', N√£o foi poss√≠vel salva novo item :/ - call_trace=/home/leandro/Documentos/Treinamentos/P√≥s Engenharia Software/MVP1/myProjects/app_api/app.py L71  
[2023-06-21 23:42:56,896] INFO _log() L224  127.0.0.1 - - [21/Jun/2023 23:42:56] "[31m[1mPOST /aplicacao HTTP/1.1[0m" 400 - - call_trace=/home/leandro/Documentos/Treinamentos/P√≥s Engenharia Software/MVP1/myProjects/app_api/env/lib/python3.11/site-packages/werkzeug/_internal.py L224 
[2023-06-21 23:44:11,237] INFO _log() L224   * Detected change in '/home/leandro/Documentos/Treinamentos/P√≥s Engenharia Software/MVP1/myProjects/app_api/app.py', reloading - call_trace=/home/leandro/Documentos/Treinamentos/P√≥s Engenharia Software/MVP1/myProjects/app_api/env/lib/python3.11/site-packages/werkzeug/_internal.py L224 
[2023-06-21 23:44:11,359] INFO _log() L224   * Restarting with stat - call_trace=/home/leandro/Documentos/Treinamentos/P√≥s Engenharia Software/MVP1/myProjects/app_api/env/lib/python3.11/site-packages/werkzeug/_internal.py L224 
[2023-06-21 23:44:22,336] ERROR log_exception() L1449 Exception on /aplicacao [POST] - call_trace=/home/leandro/Documentos/Treinamentos/P√≥s Engenharia Software/MVP1/myProjects/app_api/env/lib/python3.11/site-packages/flask/app.py L1449
Traceback (most recent call last):
  File "/home/leandro/Documentos/Treinamentos/P√≥s Engenharia Software/MVP1/myProjects/app_api/app.py", line 60, in add_aplicacao
    return apresenta_aplicacoes(aplicacao), 200
           ^^^^^^^^^^^^^^^^^^^^^^^^^^^^^^^
  File "/home/leandro/Documentos/Treinamentos/P√≥s Engenharia Software/MVP1/myProjects/app_api/schemas/aplicacao.py", line 34, in apresenta_aplicacoes
    for aplicacao in aplicacoes:
TypeError: 'Aplicacao' object is not iterable

During handling of the above exception, another exception occurred:

Traceback (most recent call last):
  File "/home/leandro/Documentos/Treinamentos/P√≥s Engenharia Software/MVP1/myProjects/app_api/env/lib/python3.11/site-packages/flask/app.py", line 2073, in wsgi_app
    response = self.full_dispatch_request()
               ^^^^^^^^^^^^^^^^^^^^^^^^^^^^
  File "/home/leandro/Documentos/Treinamentos/P√≥s Engenharia Software/MVP1/myProjects/app_api/env/lib/python3.11/site-packages/flask/app.py", line 1519, in full_dispatch_request
    rv = self.handle_user_exception(e)
         ^^^^^^^^^^^^^^^^^^^^^^^^^^^^^
  File "/home/leandro/Documentos/Treinamentos/P√≥s Engenharia Software/MVP1/myProjects/app_api/env/lib/python3.11/site-packages/flask_cors/extension.py", line 165, in wrapped_function
    return cors_after_request(app.make_response(f(*args, **kwargs)))
                                                ^^^^^^^^^^^^^^^^^^
  File "/home/leandro/Documentos/Treinamentos/P√≥s Engenharia Software/MVP1/myProjects/app_api/env/lib/python3.11/site-packages/flask/app.py", line 1517, in full_dispatch_request
    rv = self.dispatch_request()
         ^^^^^^^^^^^^^^^^^^^^^^^
  File "/home/leandro/Documentos/Treinamentos/P√≥s Engenharia Software/MVP1/myProjects/app_api/env/lib/python3.11/site-packages/flask/app.py", line 1503, in dispatch_request
    return self.ensure_sync(self.view_functions[rule.endpoint])(**req.view_args)
           ^^^^^^^^^^^^^^^^^^^^^^^^^^^^^^^^^^^^^^^^^^^^^^^^^^^^^^^^^^^^^^^^^^^^^
  File "/home/leandro/Documentos/Treinamentos/P√≥s Engenharia Software/MVP1/myProjects/app_api/env/lib/python3.11/site-packages/flask_openapi3/scaffold.py", line 191, in wrapper
    resp = _do_wrapper(
           ^^^^^^^^^^^^
  File "/home/leandro/Documentos/Treinamentos/P√≥s Engenharia Software/MVP1/myProjects/app_api/env/lib/python3.11/site-packages/flask_openapi3/do_wrapper.py", line 135, in _do_wrapper
    response = func(**request_kwargs)
               ^^^^^^^^^^^^^^^^^^^^^^
  File "/home/leandro/Documentos/Treinamentos/P√≥s Engenharia Software/MVP1/myProjects/app_api/app.py", line 70, in add_aplicacao
    error_msg = "N√£o foi poss√≠vel salva novo item :/" + e.__cause__
                ~~~~~~~~~~~~~~~~~~~~~~~~~~~~~~~~~~~~~~~~^^~~~~~~~~~
TypeError: can only concatenate str (not "NoneType") to str
[2023-06-21 23:44:22,340] INFO _log() L224  127.0.0.1 - - [21/Jun/2023 23:44:22] "[35m[1mPOST /aplicacao HTTP/1.1[0m" 500 - - call_trace=/home/leandro/Documentos/Treinamentos/P√≥s Engenharia Software/MVP1/myProjects/app_api/env/lib/python3.11/site-packages/werkzeug/_internal.py L224 
[2023-06-21 23:44:35,799] INFO _log() L224   * Detected change in '/home/leandro/Documentos/Treinamentos/P√≥s Engenharia Software/MVP1/myProjects/app_api/app.py', reloading - call_trace=/home/leandro/Documentos/Treinamentos/P√≥s Engenharia Software/MVP1/myProjects/app_api/env/lib/python3.11/site-packages/werkzeug/_internal.py L224 
[2023-06-21 23:44:35,937] INFO _log() L224   * Restarting with stat - call_trace=/home/leandro/Documentos/Treinamentos/P√≥s Engenharia Software/MVP1/myProjects/app_api/env/lib/python3.11/site-packages/werkzeug/_internal.py L224 
[2023-06-21 23:44:38,427] WARNING add_aplicacao() L65   Erro ao adicionar a aplica√ß√£o 'OUTRO TESTE2', Aplica√ß√£o de mesmo nome j√° salvo na base:/ - call_trace=/home/leandro/Documentos/Treinamentos/P√≥s Engenharia Software/MVP1/myProjects/app_api/app.py L65  
[2023-06-21 23:44:38,429] INFO _log() L224  127.0.0.1 - - [21/Jun/2023 23:44:38] "[31m[1mPOST /aplicacao HTTP/1.1[0m" 409 - - call_trace=/home/leandro/Documentos/Treinamentos/P√≥s Engenharia Software/MVP1/myProjects/app_api/env/lib/python3.11/site-packages/werkzeug/_internal.py L224 
